<?xml version="1.0" ?>
<!-- =================================================================================== -->
<!-- |    This document was autogenerated by xacro from workcell.xacro                 | -->
<!-- |    EDITING THIS FILE BY HAND IS NOT RECOMMENDED                                 | -->
<!-- =================================================================================== -->
<robot name="motoman_mh_180_120">
  <ros2_control name="SNP Blending ROS2 Control" type="system">
    <hardware>
      <plugin>fake_components/GenericSystem</plugin>
    </hardware>
    <joint name="joint_1_s">
      <command_interface name="position">
        <param name="min">-3.141592653589793</param>
        <param name="max">3.141592653589793</param>
      </command_interface>
      <command_interface name="velocity">
        <param name="min">-2.181661564992912</param>
        <param name="max">2.181661564992912</param>
      </command_interface>
      <command_interface name="acceleration"/>
      <state_interface name="position"/>
      <state_interface name="velocity"/>
      <param name="initial_position">0.0</param>
      <param name="initial_velocity">0.0</param>
    </joint>
    <joint name="joint_2_l">
      <command_interface name="position">
        <param name="min">-1.0471975511965976</param>
        <param name="max">1.3264502315156905</param>
      </command_interface>
      <command_interface name="velocity">
        <param name="min">-2.007128639793479</param>
        <param name="max">2.007128639793479</param>
      </command_interface>
      <command_interface name="acceleration"/>
      <state_interface name="position"/>
      <state_interface name="velocity"/>
      <param name="initial_position">0.0</param>
      <param name="initial_velocity">0.0</param>
    </joint>
    <joint name="joint_3_u">
      <command_interface name="position">
        <param name="min">-1.4835298641951802</param>
        <param name="max">1.5707963267948966</param>
      </command_interface>
      <command_interface name="velocity">
        <param name="min">-2.181661564992912</param>
        <param name="max">2.181661564992912</param>
      </command_interface>
      <command_interface name="acceleration"/>
      <state_interface name="position"/>
      <state_interface name="velocity"/>
      <param name="initial_position">0.0</param>
      <param name="initial_velocity">0.0</param>
    </joint>
    <joint name="joint_4_r">
      <command_interface name="position">
        <param name="min">-6.283185307179586</param>
        <param name="max">6.283185307179586</param>
      </command_interface>
      <command_interface name="velocity">
        <param name="min">-3.1764992386296798</param>
        <param name="max">3.1764992386296798</param>
      </command_interface>
      <command_interface name="acceleration"/>
      <state_interface name="position"/>
      <state_interface name="velocity"/>
      <param name="initial_position">0.0</param>
      <param name="initial_velocity">0.0</param>
    </joint>
    <joint name="joint_5_b">
      <command_interface name="position">
        <param name="min">-2.2689280275926285</param>
        <param name="max">2.2689280275926285</param>
      </command_interface>
      <command_interface name="velocity">
        <param name="min">-3.0543261909900767</param>
        <param name="max">3.0543261909900767</param>
      </command_interface>
      <command_interface name="acceleration"/>
      <state_interface name="position"/>
      <state_interface name="velocity"/>
      <param name="initial_position">0.0</param>
      <param name="initial_velocity">0.0</param>
    </joint>
    <joint name="joint_6_t">
      <command_interface name="position">
        <param name="min">-6.283185307179586</param>
        <param name="max">6.283185307179586</param>
      </command_interface>
      <command_interface name="velocity">
        <param name="min">-4.625122517784973</param>
        <param name="max">4.625122517784973</param>
      </command_interface>
      <command_interface name="acceleration"/>
      <state_interface name="position"/>
      <state_interface name="velocity"/>
      <param name="initial_position">0.0</param>
      <param name="initial_velocity">0.0</param>
    </joint>
  </ros2_control>
  <!-- link list -->
  <link name="base_link">
    <visual>
      <origin rpy="0 0 0" xyz="0 0 0"/>
      <geometry>
        <mesh filename="package://snp_blending/urdf/mh180_120/visual/base_link.stl"/>
      </geometry>
      <material name="blue">
        <color rgba="0 0 1 1"/>
      </material>
    </visual>
    <collision>
      <geometry>
        <mesh filename="package://snp_blending/urdf/mh180_120/collision/base_link.stl"/>
      </geometry>
      <material name="yellow">
        <color rgba="0 1 1 1"/>
      </material>
    </collision>
  </link>
  <link name="link_s">
    <visual>
      <origin rpy="0 0 0" xyz="0 0 0"/>
      <geometry>
        <mesh filename="package://snp_blending/urdf/mh180_120/visual/link_s.stl"/>
      </geometry>
      <material name="blue"/>
    </visual>
    <collision>
      <origin rpy="0 0 0" xyz="0 0 0"/>
      <geometry>
        <mesh filename="package://snp_blending/urdf/mh180_120/collision/link_s.stl"/>
      </geometry>
      <material name="yellow"/>
    </collision>
  </link>
  <link name="link_l">
    <visual>
      <origin rpy="0 0 0" xyz="0 0 0"/>
      <geometry>
        <mesh filename="package://snp_blending/urdf/mh180_120/visual/link_l.stl"/>
      </geometry>
      <material name="blue"/>
    </visual>
    <collision>
      <origin rpy="0 0 0" xyz="0 0 0"/>
      <geometry>
        <mesh filename="package://snp_blending/urdf/mh180_120/collision/link_l.stl"/>
      </geometry>
      <material name="yellow"/>
    </collision>
  </link>
  <link name="link_u">
    <visual>
      <origin rpy="0 0 0" xyz="0 0 0"/>
      <geometry>
        <mesh filename="package://snp_blending/urdf/mh180_120/visual/link_u.stl"/>
      </geometry>
      <material name="blue"/>
    </visual>
    <collision>
      <origin rpy="0 0 0" xyz="0 0 0"/>
      <geometry>
        <mesh filename="package://snp_blending/urdf/mh180_120/collision/link_u.stl"/>
      </geometry>
      <material name="yellow"/>
    </collision>
  </link>
  <link name="link_r">
    <visual>
      <origin rpy="0 0 0" xyz="0 0 0"/>
      <geometry>
        <mesh filename="package://snp_blending/urdf/mh180_120/visual/link_r.stl"/>
      </geometry>
      <material name="blue"/>
    </visual>
    <collision>
      <origin rpy="0 0 0" xyz="0 0 0"/>
      <geometry>
        <mesh filename="package://snp_blending/urdf/mh180_120/collision/link_r.stl"/>
      </geometry>
      <material name="yellow"/>
    </collision>
  </link>
  <link name="link_b">
    <visual>
      <origin rpy="0 0 0" xyz="0 0 0"/>
      <geometry>
        <mesh filename="package://snp_blending/urdf/mh180_120/visual/link_b.stl"/>
      </geometry>
      <material name="blue"/>
    </visual>
    <collision>
      <origin rpy="0 0 0" xyz="0 0 0"/>
      <geometry>
        <mesh filename="package://snp_blending/urdf/mh180_120/collision/link_b.stl"/>
      </geometry>
      <material name="yellow"/>
    </collision>
  </link>
  <link name="link_t">
    <visual>
      <origin rpy="0 0 0" xyz="0 0 0"/>
      <geometry>
        <mesh filename="package://snp_blending/urdf/mh180_120/visual/link_t.stl"/>
      </geometry>
      <material name="black">
        <color rgba="0 0 0 1"/>
      </material>
    </visual>
    <collision>
      <origin rpy="0 0 0" xyz="0 0 0"/>
      <geometry>
        <mesh filename="package://snp_blending/urdf/mh180_120/collision/link_t.stl"/>
      </geometry>
      <material name="black"/>
    </collision>
  </link>
  <link name="tool0"/>
  <!-- end of link list -->
  <!-- joint list -->
  <joint name="joint_1_s" type="revolute">
    <origin rpy="0 0 0" xyz="0 0 0.650"/>
    <parent link="base_link"/>
    <child link="link_s"/>
    <axis xyz="0 0 1"/>
    <limit effort="0" lower="-3.141592653589793" upper="3.141592653589793" velocity="2.181661564992912"/>
  </joint>
  <joint name="joint_2_l" type="revolute">
    <origin rpy="0 0 0" xyz="0.325 0 0"/>
    <parent link="link_s"/>
    <child link="link_l"/>
    <axis xyz="0 1 0"/>
    <limit effort="0" lower="-1.0471975511965976" upper="1.3264502315156905" velocity="2.007128639793479"/>
  </joint>
  <joint name="joint_3_u" type="revolute">
    <origin rpy="0 0 0" xyz="0 0 1.150"/>
    <parent link="link_l"/>
    <child link="link_u"/>
    <axis xyz="0 -1 0"/>
    <limit effort="0" lower="-1.4835298641951802" upper="1.5707963267948966" velocity="2.181661564992912"/>
  </joint>
  <joint name="joint_4_r" type="revolute">
    <origin rpy="0 0 0" xyz="0 0 0.3"/>
    <parent link="link_u"/>
    <child link="link_r"/>
    <axis xyz="-1 0 0"/>
    <limit effort="0" lower="-6.283185307179586" upper="6.283185307179586" velocity="3.1764992386296798"/>
  </joint>
  <joint name="joint_5_b" type="revolute">
    <origin rpy="0 0 0" xyz="1.590 0 0"/>
    <parent link="link_r"/>
    <child link="link_b"/>
    <axis xyz="0 -1 0"/>
    <limit effort="0" lower="-2.2689280275926285" upper="2.2689280275926285" velocity="3.0543261909900767"/>
  </joint>
  <joint name="joint_6_t" type="revolute">
    <origin rpy="0 0 0" xyz="0.225 0 0"/>
    <parent link="link_b"/>
    <child link="link_t"/>
    <axis xyz="-1 0 0"/>
    <limit effort="0" lower="-6.283185307179586" upper="6.283185307179586" velocity="4.625122517784973"/>
  </joint>
  <joint name="joint_6_t-tool0" type="fixed">
    <origin rpy="0 1.5707963267948966 0" xyz="0 0 0"/>
    <parent link="link_t"/>
    <child link="tool0"/>
  </joint>
  <!-- end of joint list -->
  <!-- ROS base_link to Robot Manufacturer World Coordinates transform -->
  <link name="base"/>
  <joint name="base_link-base" type="fixed">
    <origin rpy="0 0 0" xyz="0 0 0.650"/>
    <parent link="base_link"/>
    <child link="base"/>
  </joint>
  <link name="pushcorp_base">
    <visual>
      <geometry>
        <mesh filename="package://snp_blending/meshes/pushcorp/compliance_static.ply"/>
      </geometry>
    </visual>
    <collision>
      <geometry>
        <mesh filename="package://snp_blending/meshes/pushcorp/compliance_static.ply"/>
      </geometry>
    </collision>
  </link>
  <link name="pushcorp_compliance">
    <visual>
      <geometry>
        <mesh filename="package://snp_blending/meshes/pushcorp/visual/spindle.ply"/>
      </geometry>
    </visual>
    <collision>
      <geometry>
        <mesh filename="package://snp_blending/meshes/pushcorp/collision/compliance_slide.ply"/>
      </geometry>
    </collision>
    <collision>
      <geometry>
        <mesh filename="package://snp_blending/meshes/pushcorp/collision/spindle.ply"/>
      </geometry>
    </collision>
    <collision>
      <geometry>
        <mesh filename="package://snp_blending/meshes/pushcorp/collision/spindle_bracket.ply"/>
      </geometry>
    </collision>
    <!-- Grinding media -->
    <visual>
      <origin rpy="0 1.5707963267948966 0" xyz="0.2275 0 0.1115"/>
      <geometry>
        <cylinder length="0.055" radius="0.0254}"/>
      </geometry>
    </visual>
    <collision>
      <origin rpy="0 1.5707963267948966 0" xyz="0.2275 0 0.1115"/>
      <geometry>
        <cylinder length="0.055" radius="0.0254}"/>
      </geometry>
    </collision>
    <!-- Grinding media -->
    <visual>
      <origin rpy="0 1.5707963267948966 0" xyz="0.255 0 0.1115"/>
      <geometry>
        <cylinder length="0.005" radius="0.0508"/>
      </geometry>
    </visual>
    <collision>
      <origin rpy="0 1.5707963267948966 0" xyz="0.255 0 0.1115"/>
      <geometry>
        <cylinder length="0.005" radius="0.0508"/>
      </geometry>
    </collision>
  </link>
  <joint name="pushcorp_actuator" type="prismatic">
    <parent link="pushcorp_base"/>
    <child link="pushcorp_compliance"/>
    <origin rpy="0 0 0" xyz="0 0 0.0785"/>
    <axis xyz="-1 0 0"/>
    <limit effort="0" lower="-0.017779999999999997" upper="0.017779999999999997" velocity="0"/>
  </joint>
  <material name="light_gray">
    <color rgba="0.7 0.7 0.7 1"/>
  </material>
  <material name="dark_gray">
    <color rgba="0.3 0.3 0.3 1"/>
  </material>
  <link name="floor"/>
  <link name="platform">
    <visual>
      <geometry>
        <box size="2.4383999999999997 1.8288 0.127"/>
      </geometry>
      <material name="dark_gray"/>
    </visual>
    <collision>
      <geometry>
        <box size="2.4383999999999997 1.8288 0.127"/>
      </geometry>
      <material name="dark_gray"/>
    </collision>
  </link>
  <link name="robot_mount">
    <visual>
      <geometry>
        <box size="0.7239 0.7239 0.49784"/>
      </geometry>
      <material name="dark_gray"/>
    </visual>
    <collision>
      <geometry>
        <box size="0.7239 0.7239 0.49784"/>
      </geometry>
      <material name="dark_gray"/>
    </collision>
  </link>
  <link name="pushcorp_box_support_1">
    <visual>
      <geometry>
        <box size="0.038099999999999995 0.038099999999999995 1.0287"/>
      </geometry>
      <material name="light_gray"/>
    </visual>
    <collision>
      <geometry>
        <box size="0.038099999999999995 0.038099999999999995 1.0287"/>
      </geometry>
      <material name="light_gray"/>
    </collision>
  </link>
  <link name="pushcorp_box_support_2">
    <visual>
      <geometry>
        <box size="0.038099999999999995 0.038099999999999995 1.0287"/>
      </geometry>
      <material name="light_gray"/>
    </visual>
    <collision>
      <geometry>
        <box size="0.038099999999999995 0.038099999999999995 1.0287"/>
      </geometry>
      <material name="light_gray"/>
    </collision>
  </link>
  <link name="pushcorp_box">
    <visual>
      <geometry>
        <box size="0.7111999999999999 0.43179999999999996 0.762"/>
      </geometry>
      <material name="light_gray"/>
    </visual>
    <collision>
      <geometry>
        <box size="0.7111999999999999 0.43179999999999996 0.762"/>
      </geometry>
      <material name="light_gray"/>
    </collision>
  </link>
  <link name="buffy_tcp"/>
  <joint name="buffy_tcp_joint" type="fixed">
    <parent link="tool0"/>
    <child link="buffy_tcp"/>
    <origin rpy="0 1.5707963267948966 0" xyz="0.265 0 0.19"/>
  </joint>
  <joint name="floor_to_platform" type="fixed">
    <parent link="floor"/>
    <child link="platform"/>
    <origin rpy="0 0 0" xyz="0 0 0.0635"/>
  </joint>
  <joint name="platform_to_mount" type="fixed">
    <parent link="platform"/>
    <child link="robot_mount"/>
    <origin rpy="0 0 0" xyz="0 0 0.31242000000000003"/>
  </joint>
  <joint name="floor_to_pushcorp_support_1" type="fixed">
    <parent link="floor"/>
    <child link="pushcorp_box_support_1"/>
    <origin rpy="0 0 0" xyz="-0.43179999999999996 0.7746999999999999 0.64135"/>
  </joint>
  <joint name="floor_to_pushcorp_support_2" type="fixed">
    <parent link="floor"/>
    <child link="pushcorp_box_support_2"/>
    <origin rpy="0 0 0" xyz="-1.1049 0.7746999999999999 0.64135"/>
  </joint>
  <joint name="floor_to_pushcorp_box" type="fixed">
    <parent link="floor"/>
    <child link="pushcorp_box"/>
    <origin rpy="0 0 0" xyz="-0.76835 1.00965 0.7365999999999999"/>
  </joint>
  <!-- Robot to mount -->
  <joint name="mount_to_base" type="fixed">
    <parent link="robot_mount"/>
    <child link="base_link"/>
    <origin rpy="0 0 0" xyz="0 0 0.24892"/>
  </joint>
  <!-- Pushcorp to robot -->
  <joint name="tool0_to_pushcorp_base" type="fixed">
    <parent link="tool0"/>
    <child link="pushcorp_base"/>
  </joint>
  <link name="camera_color_optical_frame"/>
  <joint name="tool0_to_camera" type="fixed">
    <parent link="tool0"/>
    <child link="camera_color_optical_frame"/>
    <origin rpy="1.583081030251112 -3.122182762672128 0.002948343264348896" xyz="-0.009463772255651237 -0.1031312457873824 0.03876615960446108"/>
  </joint>
  <link name="cal_target_frame"/>
  <joint name="target_mount_to_target" type="fixed">
    <parent link="base_link"/>
    <child link="cal_target_frame"/>
    <origin rpy="3.138265142744211 -3.139826528288589 3.120448851082269" xyz="1.60586104034503 -0.05503244317187262 0.3255638469473136"/>
  </joint>
  <link name="table">
    <visual>
      <origin xyz="0.4572 0.762 -0.4699"/>
      <geometry>
        <box size="0.9144 1.524 0.9398"/>
      </geometry>
      <material name="light_gray"/>
    </visual>
    <collision>
      <origin xyz="0.4572 0.762 -0.4699"/>
      <geometry>
        <box size="0.9144 1.524 0.9398"/>
      </geometry>
      <material name="light_gray"/>
    </collision>
  </link>
  <joint name="floor_to_table" type="fixed">
    <parent link="floor"/>
    <child link="table"/>
    <origin rpy="0.0 0.0 0.0" xyz="1.593 -0.58 0.9398"/>
  </joint>
</robot>
