<?xml version="1.0" ?>
<!-- =================================================================================== -->
<!-- |    This document was autogenerated by xacro from workcell.xacro                 | -->
<!-- |    EDITING THIS FILE BY HAND IS NOT RECOMMENDED                                 | -->
<!-- =================================================================================== -->
<robot name="snp_workcell">
  <!-- link list -->
  <link name="base_link">
    <visual>
      <origin rpy="0 0 0" xyz="0 0 0"/>
      <geometry>
        <mesh filename="package://snp_support/meshes/mh180/visual/base_link.stl"/>
      </geometry>
      <material name="blue">
        <color rgba="0 0 1 1"/>
      </material>
    </visual>
    <collision>
      <geometry>
        <mesh filename="package://snp_support/meshes/mh180/collision/base_link.stl"/>
      </geometry>
      <material name="yellow">
        <color rgba="0 1 1 1"/>
      </material>
    </collision>
  </link>
  <link name="link_s">
    <visual>
      <origin rpy="0 0 0" xyz="0 0 0"/>
      <geometry>
        <mesh filename="package://snp_support/meshes/mh180/visual/link_s.stl"/>
      </geometry>
      <material name="blue"/>
    </visual>
    <collision>
      <origin rpy="0 0 0" xyz="0 0 0"/>
      <geometry>
        <mesh filename="package://snp_support/meshes/mh180/collision/link_s.stl"/>
      </geometry>
      <material name="yellow"/>
    </collision>
  </link>
  <link name="link_l">
    <visual>
      <origin rpy="0 0 0" xyz="0 0 0"/>
      <geometry>
        <mesh filename="package://snp_support/meshes/mh180/visual/link_l.stl"/>
      </geometry>
      <material name="blue"/>
    </visual>
    <collision>
      <origin rpy="0 0 0" xyz="0 0 0"/>
      <geometry>
        <mesh filename="package://snp_support/meshes/mh180/collision/link_l.stl"/>
      </geometry>
      <material name="yellow"/>
    </collision>
  </link>
  <link name="link_u">
    <visual>
      <origin rpy="0 0 0" xyz="0 0 0"/>
      <geometry>
        <mesh filename="package://snp_support/meshes/mh180_120/visual/link_u.stl"/>
      </geometry>
      <material name="blue"/>
    </visual>
    <collision>
      <origin rpy="0 0 0" xyz="0 0 0"/>
      <geometry>
        <mesh filename="package://snp_support/meshes/mh180_120/collision/link_u.stl"/>
      </geometry>
      <material name="yellow"/>
    </collision>
  </link>
  <link name="link_r">
    <visual>
      <origin rpy="0 0 0" xyz="0 0 0"/>
      <geometry>
        <mesh filename="package://snp_support/meshes/mh180_120/visual/link_r.stl"/>
      </geometry>
      <material name="blue"/>
    </visual>
    <collision>
      <origin rpy="0 0 0" xyz="0 0 0"/>
      <geometry>
        <mesh filename="package://snp_support/meshes/mh180_120/collision/link_r.stl"/>
      </geometry>
      <material name="yellow"/>
    </collision>
  </link>
  <link name="link_b">
    <visual>
      <origin rpy="0 0 0" xyz="0 0 0"/>
      <geometry>
        <mesh filename="package://snp_support/meshes/mh180/visual/link_b.stl"/>
      </geometry>
      <material name="blue"/>
    </visual>
    <collision>
      <origin rpy="0 0 0" xyz="0 0 0"/>
      <geometry>
        <mesh filename="package://snp_support/meshes/mh180/collision/link_b.stl"/>
      </geometry>
      <material name="yellow"/>
    </collision>
  </link>
  <link name="link_t">
    <visual>
      <origin rpy="0 0 0" xyz="0 0 0"/>
      <geometry>
        <mesh filename="package://snp_support/meshes/mh180/visual/link_t.stl"/>
      </geometry>
      <material name="black">
        <color rgba="0 0 0 1"/>
      </material>
    </visual>
    <collision>
      <origin rpy="0 0 0" xyz="0 0 0"/>
      <geometry>
        <mesh filename="package://snp_support/meshes/mh180/collision/link_t.stl"/>
      </geometry>
      <material name="black"/>
    </collision>
  </link>
  <link name="tool0"/>
  <!-- end of link list -->
  <!-- joint list -->
  <joint name="joint_1" type="revolute">
    <origin rpy="0 0 0" xyz="0 0 0.650"/>
    <parent link="base_link"/>
    <child link="link_s"/>
    <axis xyz="0 0 1"/>
    <limit effort="0" lower="-3.141592653589793" upper="3.141592653589793" velocity="2.181661564992912"/>
  </joint>
  <joint name="joint_2" type="revolute">
    <origin rpy="0 0 0" xyz="0.325 0 0"/>
    <parent link="link_s"/>
    <child link="link_l"/>
    <axis xyz="0 1 0"/>
    <limit effort="0" lower="-1.0471975511965976" upper="1.3264502315156905" velocity="2.007128639793479"/>
  </joint>
  <joint name="joint_3" type="revolute">
    <origin rpy="0 0 0" xyz="0 0 1.150"/>
    <parent link="link_l"/>
    <child link="link_u"/>
    <axis xyz="0 -1 0"/>
    <limit effort="0" lower="-1.4835298641951802" upper="1.5707963267948966" velocity="2.181661564992912"/>
  </joint>
  <joint name="joint_4" type="revolute">
    <origin rpy="0 0 0" xyz="0 0 0.3"/>
    <parent link="link_u"/>
    <child link="link_r"/>
    <axis xyz="-1 0 0"/>
    <limit effort="0" lower="-6.283185307179586" upper="6.283185307179586" velocity="3.1764992386296798"/>
  </joint>
  <joint name="joint_5" type="revolute">
    <origin rpy="0 0 0" xyz="1.590 0 0"/>
    <parent link="link_r"/>
    <child link="link_b"/>
    <axis xyz="0 -1 0"/>
    <limit effort="0" lower="-2.2689280275926285" upper="2.2689280275926285" velocity="3.0543261909900767"/>
  </joint>
  <joint name="joint_6" type="revolute">
    <origin rpy="0 0 0" xyz="0.225 0 0"/>
    <parent link="link_b"/>
    <child link="link_t"/>
    <axis xyz="-1 0 0"/>
    <limit effort="0" lower="-6.283185307179586" upper="6.283185307179586" velocity="4.625122517784973"/>
  </joint>
  <joint name="joint_6-tool0" type="fixed">
    <origin rpy="0 1.5707963267948966 0" xyz="0 0 0"/>
    <parent link="link_t"/>
    <child link="tool0"/>
  </joint>
  <!-- end of joint list -->
  <!-- ROS base_link to Robot Manufacturer World Coordinates transform -->
  <link name="base"/>
  <joint name="base_link-base" type="fixed">
    <origin rpy="0 0 0" xyz="0 0 0.650"/>
    <parent link="base_link"/>
    <child link="base"/>
  </joint>
  <link name="pushcorp_base">
    <visual>
      <geometry>
        <mesh filename="package://snp_support/meshes/pushcorp/pushcorp_base.dae"/>
      </geometry>
    </visual>
    <collision>
      <geometry>
        <mesh filename="package://snp_support/meshes/pushcorp/pushcorp_base.dae"/>
      </geometry>
    </collision>
  </link>
  <link name="pushcorp_compliance">
    <visual>
      <geometry>
        <mesh filename="package://snp_support/meshes/pushcorp/pushcorp_compliance.dae"/>
      </geometry>
    </visual>
    <collision>
      <geometry>
        <mesh filename="package://snp_support/meshes/pushcorp/pushcorp_compliance.dae"/>
      </geometry>
    </collision>
  </link>
  <link name="camera_link"/>
  <link name="target_base_link">
    <visual>
      <origin rpy="1.5707963267948966 0 3.141592653589793" xyz="0.37565 0.2809875 0"/>
      <geometry>
        <mesh filename="package://snp_support/meshes/rosWorldCalib.dae"/>
      </geometry>
    </visual>
  </link>
  <joint name="tool0_to_pushcorp_base" type="fixed">
    <parent link="tool0"/>
    <child link="pushcorp_base"/>
    <origin rpy="1.5707963267948966 0 3.141592653589793" xyz="0 0 0.01635"/>
    <axis xyz="0 0 0"/>
  </joint>
  <joint name="robot_to_camera_joint" type="fixed">
    <parent link="tool0"/>
    <child link="camera_link"/>
    <origin rpy="0 0 0" xyz="0 0 0"/>
    <axis xyz="0 0 0"/>
  </joint>
  <joint name="world_to_target_joint" type="fixed">
    <parent link="floor"/>
    <child link="target_base_link"/>
    <origin rpy="0.004 -0.004 -1.628" xyz="0.555 0.061 0.126"/>
    <axis xyz="0 0 0"/>
  </joint>
  <link name="camera_color_optical_frame"/>
  <link name="target_cal_frame"/>
  <joint name="camera_cal_joint" type="fixed">
    <parent link="camera_link"/>
    <child link="camera_color_optical_frame"/>
    <origin wxyz="0.5118596229748543 -0.5074314040915237 0.4900425218487801 -0.4902768843111336" xyz="0.085549560652492 -0.1732631672558103 0.1329373703855808"/>
  </joint>
  <joint name="target_cal_joint" type="fixed">
    <parent link="floor"/>
    <child link="target_cal_frame"/>
    <origin wxyz="0.6869783604862724 -0.001114251051880176 -0.003909064875724348 -0.7266665052690842" xyz="0.555641489380775 0.05956001933889868 0.1229851433910979"/>
  </joint>
  <!-- TODO do we care about effort and velocity limits?-->
  <joint name="pushcorp_actuator" type="prismatic">
    <parent link="pushcorp_base"/>
    <child link="pushcorp_compliance"/>
    <origin rpy="0 0 0" xyz="0 0 0"/>
    <axis xyz="-1 0 0"/>
    <limit effort="0" lower="-0.01778" upper="0.01778" velocity="0"/>
  </joint>
  <material name="light_gray">
    <color rgba="0.7 0.7 0.7 1"/>
  </material>
  <material name="dark_gray">
    <color rgba="0.3 0.3 0.3 1"/>
  </material>
  <link name="floor"/>
  <link name="platform">
    <visual>
      <geometry>
        <box size="2.4383999999999997 1.8288 0.127"/>
      </geometry>
      <material name="dark_gray"/>
    </visual>
    <collision>
      <geometry>
        <box size="2.4383999999999997 1.8288 0.127"/>
      </geometry>
    </collision>
  </link>
  <link name="robot_mount">
    <visual>
      <geometry>
        <box size="0.7239 0.7239 0.49784"/>
      </geometry>
      <material name="dark_gray"/>
    </visual>
    <collision>
      <geometry>
        <box size="0.7239 0.7239 0.49784"/>
      </geometry>
    </collision>
  </link>
  <link name="pushcorp_box_support_1">
    <visual>
      <geometry>
        <box size="0.038099999999999995 0.038099999999999995 1.0287"/>
      </geometry>
      <material name="dark_gray"/>
    </visual>
    <collision>
      <geometry>
        <box size="0.038099999999999995 0.038099999999999995 1.0287"/>
      </geometry>
    </collision>
  </link>
  <link name="pushcorp_box_support_2">
    <visual>
      <geometry>
        <box size="0.038099999999999995 0.038099999999999995 1.0287"/>
      </geometry>
      <material name="dark_gray"/>
    </visual>
    <collision>
      <geometry>
        <box size="0.038099999999999995 0.038099999999999995 1.0287"/>
      </geometry>
    </collision>
  </link>
  <link name="pushcorp_box">
    <visual>
      <geometry>
        <box size="0.7111999999999999 0.43179999999999996 0.762"/>
      </geometry>
      <material name="light_gray"/>
    </visual>
    <collision>
      <geometry>
        <box size="0.7111999999999999 0.43179999999999996 0.762"/>
      </geometry>
    </collision>
  </link>
  <link name="control_boxes">
    <visual>
      <geometry>
        <box size="3.302 0.9652 1.524"/>
      </geometry>
      <material name="light_gray"/>
    </visual>
    <collision>
      <geometry>
        <box size="3.302 0.9652 1.524"/>
      </geometry>
    </collision>
  </link>
  <joint name="floor_to_platform" type="fixed">
    <parent link="floor"/>
    <child link="platform"/>
    <origin rpy="0 0 0" xyz="0 0 0.0635"/>
    <axis xyz="0 0 0"/>
  </joint>
  <joint name="platform_to_mount" type="fixed">
    <parent link="platform"/>
    <child link="robot_mount"/>
    <origin rpy="0 0 0" xyz="0 0 0.31242000000000003"/>
    <axis xyz="0 0 0"/>
  </joint>
  <joint name="floor_to_control_boxes" type="fixed">
    <parent link="floor"/>
    <child link="control_boxes"/>
    <origin rpy="0 0 0" xyz="1.7526 -1.9049999999999998 0.762"/>
    <axis xyz="0 0 0"/>
  </joint>
  <joint name="mount_to_base" type="fixed">
    <parent link="robot_mount"/>
    <child link="base_link"/>
    <origin rpy="0 0 0" xyz="0 0 0.24892"/>
    <axis xyz="0 0 0"/>
  </joint>
  <joint name="floor_to_pushcorp_support_1" type="fixed">
    <parent link="floor"/>
    <child link="pushcorp_box_support_1"/>
    <origin rpy="0 0 0" xyz="-0.43179999999999996 0.7746999999999999 0.64135"/>
    <axis xyz="0 0 0"/>
  </joint>
  <joint name="floor_to_pushcorp_support_2" type="fixed">
    <parent link="floor"/>
    <child link="pushcorp_box_support_2"/>
    <origin rpy="0 0 0" xyz="-1.1049 0.7746999999999999 0.64135"/>
    <axis xyz="0 0 0"/>
  </joint>
  <joint name="floor_to_pushcorp_box" type="fixed">
    <parent link="floor"/>
    <child link="pushcorp_box"/>
    <origin rpy="0 0 0" xyz="-0.76835 1.00965 0.7365999999999999"/>
    <axis xyz="0 0 0"/>
  </joint>
</robot>
